[2020-04-26 20:05:23,744] {{taskinstance.py:655}} INFO - Dependencies all met for <TaskInstance: ReclameAqui.consulta_dados_company_date 2020-04-26T20:05:16.329895+00:00 [queued]>
[2020-04-26 20:05:23,791] {{taskinstance.py:655}} INFO - Dependencies all met for <TaskInstance: ReclameAqui.consulta_dados_company_date 2020-04-26T20:05:16.329895+00:00 [queued]>
[2020-04-26 20:05:23,792] {{taskinstance.py:866}} INFO - 
--------------------------------------------------------------------------------
[2020-04-26 20:05:23,792] {{taskinstance.py:867}} INFO - Starting attempt 1 of 2
[2020-04-26 20:05:23,793] {{taskinstance.py:868}} INFO - 
--------------------------------------------------------------------------------
[2020-04-26 20:05:23,828] {{taskinstance.py:887}} INFO - Executing <Task(PythonOperator): consulta_dados_company_date> on 2020-04-26T20:05:16.329895+00:00
[2020-04-26 20:05:23,832] {{standard_task_runner.py:53}} INFO - Started process 26996 to run task
[2020-04-26 20:05:24,048] {{logging_mixin.py:112}} INFO - Running %s on host %s <TaskInstance: ReclameAqui.consulta_dados_company_date 2020-04-26T20:05:16.329895+00:00 [running]> 030a07de9129.semantix
[2020-04-26 20:05:24,110] {{logging_mixin.py:112}} INFO - DEBUG GET: {'company': 'Cielo', 'date': '20190101'}
[2020-04-26 20:05:24,111] {{logging_mixin.py:112}} INFO - DEBUG GET 1: http://api_persistenciadados:5005/scores/
[2020-04-26 20:05:24,113] {{logging_mixin.py:112}} INFO - DEBUG GET 2: {'company': 'Cielo', 'date': '20190101'}
[2020-04-26 20:05:24,155] {{taskinstance.py:1128}} ERROR - 'Response' object has no attribute 'txt'
Traceback (most recent call last):
  File "/usr/local/lib/python3.7/site-packages/airflow/models/taskinstance.py", line 966, in _run_raw_task
    result = task_copy.execute(context=context)
  File "/usr/local/lib/python3.7/site-packages/airflow/operators/python_operator.py", line 113, in execute
    return_value = self.execute_callable()
  File "/usr/local/lib/python3.7/site-packages/airflow/operators/python_operator.py", line 118, in execute_callable
    return self.python_callable(*self.op_args, **self.op_kwargs)
  File "/usr/local/airflow/dags/scripts/requests_database.py", line 66, in crud_main
    main_response = get_database(collection, params)
  File "/usr/local/airflow/dags/scripts/requests_database.py", line 34, in get_database
    print('DEBUG GET 3: {}'.format(response.txt) )
AttributeError: 'Response' object has no attribute 'txt'
[2020-04-26 20:05:24,161] {{taskinstance.py:1151}} INFO - Marking task as UP_FOR_RETRY
[2020-04-26 20:05:33,659] {{logging_mixin.py:112}} INFO - [2020-04-26 20:05:33,658] {{local_task_job.py:103}} INFO - Task exited with return code 1
