[2020-04-26 22:53:37,718] {{taskinstance.py:655}} INFO - Dependencies all met for <TaskInstance: ReclameAqui-scraping_scores.persiste_dados_mongodb 2020-04-26T22:52:40.740469+00:00 [queued]>
[2020-04-26 22:53:37,756] {{taskinstance.py:655}} INFO - Dependencies all met for <TaskInstance: ReclameAqui-scraping_scores.persiste_dados_mongodb 2020-04-26T22:52:40.740469+00:00 [queued]>
[2020-04-26 22:53:37,756] {{taskinstance.py:866}} INFO - 
--------------------------------------------------------------------------------
[2020-04-26 22:53:37,756] {{taskinstance.py:867}} INFO - Starting attempt 1 of 2
[2020-04-26 22:53:37,756] {{taskinstance.py:868}} INFO - 
--------------------------------------------------------------------------------
[2020-04-26 22:53:37,901] {{taskinstance.py:887}} INFO - Executing <Task(PythonOperator): persiste_dados_mongodb> on 2020-04-26T22:52:40.740469+00:00
[2020-04-26 22:53:37,906] {{standard_task_runner.py:53}} INFO - Started process 1304 to run task
[2020-04-26 22:53:37,981] {{logging_mixin.py:112}} INFO - Running %s on host %s <TaskInstance: ReclameAqui-scraping_scores.persiste_dados_mongodb 2020-04-26T22:52:40.740469+00:00 [running]> 030a07de9129.semantix
[2020-04-26 22:53:38,012] {{taskinstance.py:1128}} ERROR - crud_main() got an unexpected keyword argument 'conf'
Traceback (most recent call last):
  File "/usr/local/lib/python3.7/site-packages/airflow/models/taskinstance.py", line 966, in _run_raw_task
    result = task_copy.execute(context=context)
  File "/usr/local/lib/python3.7/site-packages/airflow/operators/python_operator.py", line 113, in execute
    return_value = self.execute_callable()
  File "/usr/local/lib/python3.7/site-packages/airflow/operators/python_operator.py", line 118, in execute_callable
    return self.python_callable(*self.op_args, **self.op_kwargs)
TypeError: crud_main() got an unexpected keyword argument 'conf'
[2020-04-26 22:53:38,014] {{taskinstance.py:1151}} INFO - Marking task as UP_FOR_RETRY
[2020-04-26 22:53:47,701] {{logging_mixin.py:112}} INFO - [2020-04-26 22:53:47,701] {{local_task_job.py:103}} INFO - Task exited with return code 1
