[2020-04-26 17:14:01,224] {{taskinstance.py:655}} INFO - Dependencies all met for <TaskInstance: ReclameAqui.persiste_dados_mongodb 2020-04-26T17:13:56.101542+00:00 [queued]>
[2020-04-26 17:14:01,256] {{taskinstance.py:655}} INFO - Dependencies all met for <TaskInstance: ReclameAqui.persiste_dados_mongodb 2020-04-26T17:13:56.101542+00:00 [queued]>
[2020-04-26 17:14:01,256] {{taskinstance.py:866}} INFO - 
--------------------------------------------------------------------------------
[2020-04-26 17:14:01,257] {{taskinstance.py:867}} INFO - Starting attempt 1 of 2
[2020-04-26 17:14:01,257] {{taskinstance.py:868}} INFO - 
--------------------------------------------------------------------------------
[2020-04-26 17:14:01,290] {{taskinstance.py:887}} INFO - Executing <Task(BashOperator): persiste_dados_mongodb> on 2020-04-26T17:13:56.101542+00:00
[2020-04-26 17:14:01,299] {{standard_task_runner.py:53}} INFO - Started process 20776 to run task
[2020-04-26 17:14:01,466] {{logging_mixin.py:112}} INFO - Running %s on host %s <TaskInstance: ReclameAqui.persiste_dados_mongodb 2020-04-26T17:13:56.101542+00:00 [running]> 61b2702b37e2.semantix
[2020-04-26 17:14:01,542] {{bash_operator.py:82}} INFO - Tmp dir root location: 
 /tmp
[2020-04-26 17:14:01,548] {{bash_operator.py:105}} INFO - Temporary script location: /tmp/airflowtmp1oevbcq9/persiste_dados_mongodbf93yajg3
[2020-04-26 17:14:01,549] {{bash_operator.py:115}} INFO - Running command: ../scripts/requests_database.py --metod POST --company Cielo --collection scores --jsondata {'answered': '6666', 'reclamations': '6151', 'response_time': '15 dias e 21 horas ', 'unanswered': '113'}
[2020-04-26 17:14:01,573] {{bash_operator.py:122}} INFO - Output:
[2020-04-26 17:14:01,576] {{bash_operator.py:126}} INFO - /tmp/airflowtmp1oevbcq9/persiste_dados_mongodbf93yajg3: line 1: ../scripts/requests_database.py: No such file or directory
[2020-04-26 17:14:01,577] {{bash_operator.py:130}} INFO - Command exited with return code 127
[2020-04-26 17:14:01,606] {{taskinstance.py:1128}} ERROR - Bash command failed
Traceback (most recent call last):
  File "/usr/local/lib/python3.7/site-packages/airflow/models/taskinstance.py", line 966, in _run_raw_task
    result = task_copy.execute(context=context)
  File "/usr/local/lib/python3.7/site-packages/airflow/operators/bash_operator.py", line 134, in execute
    raise AirflowException("Bash command failed")
airflow.exceptions.AirflowException: Bash command failed
[2020-04-26 17:14:01,610] {{taskinstance.py:1151}} INFO - Marking task as UP_FOR_RETRY
[2020-04-26 17:14:11,193] {{logging_mixin.py:112}} INFO - [2020-04-26 17:14:11,192] {{local_task_job.py:103}} INFO - Task exited with return code 1
